[1,"==> quarto preview model.qmd --to html --no-watch-inputs --no-browse\n\n"]
[1,"- The project is out-of-sync -- use `renv::status()` for details.\r\n"]
[1,"\r\n\r\nprocessing file: model.qmd\r\n\r  |                                                          \r  |                                                    |   0%\r  |                                                          \r  |...                                                 |   5%                  \r  |                                                          \r  |.....                                               |  11% [unnamed-chunk-1]"]
[1,"\r  |                                                          \r  |........                                            |  16%                  \r  |                                                          \r  |...........                                         |  21% [unnamed-chunk-2]"]
[1,"\r  |                                                          \r  |..............                                      |  26%                  \r  |                                                          \r  |................                                    |  32% [unnamed-chunk-3]"]
[1,"\r  |                                                          \r  |...................                                 |  37%                  \r  |                                                          \r  |......................                              |  42% [unnamed-chunk-4]"]
[1,"\r  |                                                          \r  |.........................                           |  47%                  \r  |                                                          \r  |...........................                         |  53% [unnamed-chunk-5]"]
[1,"\n\n\nQuitting from lines 62-72 [unnamed-chunk-5] (model.qmd)\nError in `py_call_impl()`:\n! requests.exceptions.ConnectionError: HTTPConnectionPool(host='127.0.0.1', port=8080): Max retries exceeded with url: /predict (Caused by NewConnectionError('<urllib3.connection.HTTPConnection object at 0x0000023AF627E780>: Failed to establish a new connection: [WinError 10061] No connection could be made because the target machine actively refused it'))\nRun `reticulate::py_last_error()` for details.\nBacktrace:\n  1. global .main()\n  2. execute(...)\n  3. rmarkdown::render(...)\n  4. knitr::knit(knit_input, knit_output, envir = envir, quiet = quiet)\n  5. knitr:::process_file(text, output)\n     ...\n 15. knitr (local) engine(options)\n 16. reticulate::eng_python(options)\n 17. reticulate:::py_compile_eval(snippet, compile_mode)\n 20. builtins$eval(compiled, globals, locals)\n 21. reticulate:::py_call_impl(callable, call_args$unnamed, call_args$named)\n\r                                                                                                            \nExecution halted\n"]
